{
    "registryname": "assembly_mk2",
    "localizedname": "Assembling Machine MK2",
    "requires-blueprint": true,
    "color": "7aabfa",
	"parts": [
        {
            "x": -1,
            "y": 0,
            "z": 1,
            "elements": [
                "astralsorcery:blockinfusedwood@0"
            ]
        },
        {
            "x": -2,
            "y": 0,
            "z": 2,
            "elements": [
                "enderio:block_alloy@3"
            ]
        },
        {
            "x": -1,
            "y": 0,
            "z": 0,
            "elements": [
                "modularmachinery:blockoutputbus@0",
				"modularmachinery:blockoutputbus@1",
				"modularmachinery:blockoutputbus@2",
				"modularmachinery:blockoutputbus@3",
				"modularmachinery:blockoutputbus@4",
				"modularmachinery:blockoutputbus@5",
				"modularmachinery:blockoutputbus@6",
				"modularmachinery:blockinputbus@1",
				"modularmachinery:blockinputbus@2",
				"modularmachinery:blockinputbus@3",
				"modularmachinery:blockinputbus@4",
				"modularmachinery:blockinputbus@5",
				"modularmachinery:blockinputbus@6",
				"modularmachinery:blockenergyinputhatch@0",
				"modularmachinery:blockenergyinputhatch@1",
				"modularmachinery:blockenergyinputhatch@2",
				"modularmachinery:blockenergyinputhatch@3",
				"modularmachinery:blockenergyinputhatch@4",
				"modularmachinery:blockenergyinputhatch@5",
				"modularmachinery:blockenergyinputhatch@6",
                "modularmachinery:blockenergyinputhatch@7"
            ]
        },
        {
            "x": 0,
            "y": 0,
            "z": 1,
            "elements": [
                "astralsorcery:blockinfusedwood@0"
            ]
        },
        {
            "x": -1,
            "y": 0,
            "z": 2,
            "elements": [
                "enderio:block_alloy@3"
            ]
        },
        {
            "x": 1,
            "y": 0,
            "z": 0,
            "elements": [
                "modularmachinery:blockinputbus@1",
				"modularmachinery:blockinputbus@2",
				"modularmachinery:blockinputbus@3",
				"modularmachinery:blockinputbus@4",
				"modularmachinery:blockinputbus@5",
				"modularmachinery:blockinputbus@6",
				"modularmachinery:blockenergyinputhatch@0",
				"modularmachinery:blockenergyinputhatch@1",
				"modularmachinery:blockenergyinputhatch@2",
				"modularmachinery:blockenergyinputhatch@3",
				"modularmachinery:blockenergyinputhatch@4",
				"modularmachinery:blockenergyinputhatch@5",
				"modularmachinery:blockenergyinputhatch@6",
				"modularmachinery:blockoutputbus@0",
				"modularmachinery:blockoutputbus@1",
				"modularmachinery:blockoutputbus@2",
				"modularmachinery:blockoutputbus@3",
				"modularmachinery:blockoutputbus@4",
				"modularmachinery:blockoutputbus@5",
				"modularmachinery:blockoutputbus@6"
            ]
        },
        {
            "x": -2,
            "y": 0,
            "z": 0,
            "elements": [
                "enderio:block_alloy@3"
            ]
        },
        {
            "x": 1,
            "y": 0,
            "z": 1,
            "elements": [
                "astralsorcery:blockinfusedwood@0"
            ]
        },
        {
            "x": 0,
            "y": 0,
            "z": 2,
            "elements": [
                "modularmachinery:blockenergyinputhatch@0",
				"modularmachinery:blockenergyinputhatch@1",
				"modularmachinery:blockenergyinputhatch@2",
				"modularmachinery:blockenergyinputhatch@3",
				"modularmachinery:blockenergyinputhatch@4",
				"modularmachinery:blockenergyinputhatch@5",
				"modularmachinery:blockenergyinputhatch@6",
				"modularmachinery:blockoutputbus@0",
				"modularmachinery:blockoutputbus@1",
				"modularmachinery:blockoutputbus@2",
				"modularmachinery:blockoutputbus@3",
				"modularmachinery:blockoutputbus@4",
				"modularmachinery:blockoutputbus@5",
				"modularmachinery:blockoutputbus@6",
				"modularmachinery:blockinputbus@1",
				"modularmachinery:blockinputbus@2",
				"modularmachinery:blockinputbus@3",
				"modularmachinery:blockinputbus@4",
				"modularmachinery:blockinputbus@5",
				"modularmachinery:blockinputbus@6"
            ]
        },
        {
            "x": 2,
            "y": 0,
            "z": 0,
            "elements": [
                "enderio:block_alloy@3"
            ]
        },
        {
            "x": 1,
            "y": 0,
            "z": 2,
            "elements": [
                "enderio:block_alloy@3"
            ]
        },
        {
            "x": 2,
            "y": 0,
            "z": 1,
            "elements": [
                "enderio:block_alloy@3"
            ]
        },
        {
            "x": 2,
            "y": 0,
            "z": 2,
            "elements": [
                "enderio:block_alloy@3"
            ]
        },
        {
            "x": 2,
            "y": -1,
            "z": 0,
            "elements": [
                "enderio:block_alloy@1"
            ]
        },
        {
            "x": 1,
            "y": -1,
            "z": 0,
            "elements": [
                "enderio:block_alloy@1"
            ]
        },
        {
            "x": -2,
            "y": 1,
            "z": 0,
            "elements": [
                "astralsorcery:blockblackmarble@0"
            ]
        },
        {
            "x": 0,
            "y": -1,
            "z": 0,
            "elements": [
                "enderio:block_alloy@1"
            ]
        },
        {
            "x": -2,
            "y": 1,
            "z": 1,
            "elements": [
                "astralsorcery:blockblackmarble@0"
            ]
        },
        {
            "x": -1,
            "y": 1,
            "z": 0,
            "elements": [
                "astralsorcery:blockblackmarble@0"
            ]
        },
        {
            "x": -1,
            "y": -1,
            "z": 0,
            "elements": [
                "enderio:block_alloy@1"
            ]
        },
        {
            "x": -2,
            "y": 1,
            "z": 2,
            "elements": [
                "astralsorcery:blockblackmarble@0"
            ]
        },
        {
            "x": 0,
            "y": 1,
            "z": 0,
            "elements": [
                "astralsorcery:blockblackmarble@0"
            ]
        },
        {
            "x": -1,
            "y": 1,
            "z": 1,
            "elements": [
                "astralsorcery:blockblackmarble@0"
            ]
        },
        {
            "x": -2,
            "y": -1,
            "z": 0,
            "elements": [
                "enderio:block_alloy@1"
            ]
        },
        {
            "x": -2,
            "y": -1,
            "z": 1,
            "elements": [
                "enderio:block_alloy@1"
            ]
        },
        {
            "x": -1,
            "y": 1,
            "z": 2,
            "elements": [
                "astralsorcery:blockblackmarble@0"
            ]
        },
        {
            "x": 1,
            "y": 1,
            "z": 0,
            "elements": [
                "astralsorcery:blockblackmarble@0"
            ]
        },
        {
            "x": 0,
            "y": 1,
            "z": 1,
            "elements": [
                "astralsorcery:blockblackmarble@0"
            ]
        },
        {
            "x": -2,
            "y": -1,
            "z": 2,
            "elements": [
                "enderio:block_alloy@1"
            ]
        },
        {
            "x": -1,
            "y": -1,
            "z": 1,
            "elements": [
                "enderio:block_alloy@1"
            ]
        },
        {
            "x": 0,
            "y": 1,
            "z": 2,
            "elements": [
                "astralsorcery:blockblackmarble@0"
            ]
        },
        {
            "x": 2,
            "y": 1,
            "z": 0,
            "elements": [
                "astralsorcery:blockblackmarble@0"
            ]
        },
        {
            "x": 1,
            "y": 1,
            "z": 1,
            "elements": [
                "astralsorcery:blockblackmarble@0"
            ]
        },
        {
            "x": -1,
            "y": -1,
            "z": 2,
            "elements": [
                "enderio:block_alloy@1"
            ]
        },
        {
            "x": 0,
            "y": -1,
            "z": 1,
            "elements": [
                "enderio:block_alloy@1"
            ]
        },
        {
            "x": 1,
            "y": 1,
            "z": 2,
            "elements": [
                "astralsorcery:blockblackmarble@0"
            ]
        },
        {
            "x": 2,
            "y": 1,
            "z": 1,
            "elements": [
                "astralsorcery:blockblackmarble@0"
            ]
        },
        {
            "x": 0,
            "y": -1,
            "z": 2,
            "elements": [
                "enderio:block_alloy@1"
            ]
        },
        {
            "x": 1,
            "y": -1,
            "z": 1,
            "elements": [
                "enderio:block_alloy@1"
            ]
        },
        {
            "x": 2,
            "y": 1,
            "z": 2,
            "elements": [
                "astralsorcery:blockblackmarble@0"
            ]
        },
        {
            "x": 2,
            "y": -1,
            "z": 1,
            "elements": [
                "enderio:block_alloy@1"
            ]
        },
        {
            "x": 1,
            "y": -1,
            "z": 2,
            "elements": [
                "enderio:block_alloy@1"
            ]
        },
        {
            "x": 2,
            "y": -1,
            "z": 2,
            "elements": [
                "enderio:block_alloy@1"
            ]
        },
        {
            "x": -2,
            "y": 0,
            "z": 1,
            "elements": [
                "enderio:block_alloy@3"
            ]
        }
    ],
    "modifiers": [
        {
            "elements": "contenttweaker:mmupgrade_speed",
            "x": 0,
            "y": 1,
            "z": 0,
            "description": "Replace block above controller with MM Machine Speed Upgrade\nfor double processing speed",
            "modifier": {
                "io": "input",
                "target": "duration",
                "operation": 1,
                "multiplier": -2.0
            }
        },
        {
            "elements": "contenttweaker:mmupgrade_efficiancy_item",
            "x": 0,
            "y": 1,
            "z": 0,
            "description": "Replace block above controller with MM Machine Speed Upgrade\nfor double item output",
            "modifier": {
                "io": "output",
                "target": "item",
                "operation": 1,
                "multiplier": 2.0
            }
        },
        {
            "elements": "contenttweaker:mmupgrade_efficiancy_fluid",
            "x": 0,
            "y": 1,
            "z": 0,
            "description": "Replace block above controller with MM Machine Speed Upgrade\nfor double fluid output",
            "modifier": {
                "io": "output",
                "target": "fluid",
                "operation": 1,
                "multiplier": 2.0
            }
        },
        {
            "elements": "contenttweaker:mmupgrade_efficiancy_energy",
            "x": 0,
            "y": 1,
            "z": 0,
            "description": "Replace block above controller with MM Machine Speed Upgrade\nfor double energy output",
            "modifier": {
                "io": "output",
                "target": "energy",
                "operation": 1,
                "multiplier": 2.0
            }
        }
    ]
}
