{
    "registryname": "neutron_reformer",
    "localizedname": "Neutron Reformer",
    "requires-blueprint": false,
    "color": "ebebeb",
    "parts": [
        {
            "x": -1,
            "y": 0,
            "z": 0,
            "elements": [
                "contenttweaker:sub_block_holder_1@9"
            ]
        },
        {
            "x": 1,
            "y": 2,
            "z": 1,
            "elements": [
                "enderio:block_fused_glass@1",
				"enderio:block_fused_glass@2",
				"enderio:block_fused_glass@3",
				"enderio:block_fused_glass@4",
				"enderio:block_fused_glass@5",
				"enderio:block_fused_glass@6",
				"enderio:block_fused_glass@7",
				"enderio:block_fused_glass@8",
				"enderio:block_fused_glass@9",
				"enderio:block_fused_glass@10",
				"enderio:block_fused_glass@11",
				"enderio:block_fused_glass@12",
				"enderio:block_fused_glass@13",
				"enderio:block_fused_glass@14",
				"enderio:block_fused_glass@15"
            ]
        },
        {
            "x": 1,
            "y": 0,
            "z": 0,
            "elements": [
                "contenttweaker:sub_block_holder_1@9"
            ]
        },
        {
            "x": -1,
            "y": 0,
            "z": 2,
            "elements": [
                "contenttweaker:sub_block_holder_1@9"
            ]
        },
        {
            "x": 0,
            "y": 0,
            "z": 2,
            "elements": [
                "modularmachinery:blockenergyinputhatch@0",
                "modularmachinery:blockenergyinputhatch@1",
                "modularmachinery:blockenergyinputhatch@2",
                "modularmachinery:blockenergyinputhatch@3",
                "modularmachinery:blockenergyinputhatch@4",
                "modularmachinery:blockenergyinputhatch@5",
                "modularmachinery:blockenergyinputhatch@6",
                "modularmachinery:blockenergyinputhatch@7",
                "modularmachinery:blockinputbus@0",
                "modularmachinery:blockinputbus@1",
                "modularmachinery:blockinputbus@2",
                "modularmachinery:blockinputbus@3",
                "modularmachinery:blockinputbus@4",
                "modularmachinery:blockinputbus@5",
                "modularmachinery:blockinputbus@6",
                "modularmachinery:blockoutputbus@0",
                "modularmachinery:blockoutputbus@1",
                "modularmachinery:blockoutputbus@2",
                "modularmachinery:blockoutputbus@3",
                "modularmachinery:blockoutputbus@4",
                "modularmachinery:blockoutputbus@5",
                "modularmachinery:blockoutputbus@6"
            ]
        },
        {
            "x": 1,
            "y": 0,
            "z": 2,
            "elements": [
                "contenttweaker:sub_block_holder_1@9"
            ]
        },
        {
            "x": -1,
            "y": 7,
            "z": 1,
            "elements": [
                "actuallyadditions:block_quartz_stair"
            ]
        },
        {
            "x": -1,
            "y": 5,
            "z": 0,
            "elements": [
                "botania:livingrock@1"
            ]
        },
        {
            "x": 0,
            "y": 7,
            "z": 1,
            "elements": [
                "actuallyadditions:block_quartz_slab"
            ]
        },
        {
            "x": 0,
            "y": 5,
            "z": 0,
            "elements": [
                "enderio:block_fused_glass@1",
				"enderio:block_fused_glass@2",
				"enderio:block_fused_glass@3",
				"enderio:block_fused_glass@4",
				"enderio:block_fused_glass@5",
				"enderio:block_fused_glass@6",
				"enderio:block_fused_glass@7",
				"enderio:block_fused_glass@8",
				"enderio:block_fused_glass@9",
				"enderio:block_fused_glass@10",
				"enderio:block_fused_glass@11",
				"enderio:block_fused_glass@12",
				"enderio:block_fused_glass@13",
				"enderio:block_fused_glass@14",
				"enderio:block_fused_glass@15"
            ]
        },
        {
            "x": 1,
            "y": 7,
            "z": 1,
            "elements": [
                "actuallyadditions:block_quartz_stair"
            ]
        },
        {
            "x": -1,
            "y": 5,
            "z": 2,
            "elements": [
                "botania:livingrock@1"
            ]
        },
        {
            "x": 1,
            "y": 5,
            "z": 0,
            "elements": [
                "botania:livingrock@1"
            ]
        },
        {
            "x": 0,
            "y": 5,
            "z": 2,
            "elements": [
                "enderio:block_fused_glass@1",
				"enderio:block_fused_glass@2",
				"enderio:block_fused_glass@3",
				"enderio:block_fused_glass@4",
				"enderio:block_fused_glass@5",
				"enderio:block_fused_glass@6",
				"enderio:block_fused_glass@7",
				"enderio:block_fused_glass@8",
				"enderio:block_fused_glass@9",
				"enderio:block_fused_glass@10",
				"enderio:block_fused_glass@11",
				"enderio:block_fused_glass@12",
				"enderio:block_fused_glass@13",
				"enderio:block_fused_glass@14",
				"enderio:block_fused_glass@15"
            ]
        },
        {
            "x": 0,
            "y": 3,
            "z": 1,
            "elements": [
                "actuallyadditions:block_crystal_empowered@2"
            ]
        },
        {
            "x": 1,
            "y": 5,
            "z": 2,
            "elements": [
                "botania:livingrock@1"
            ]
        },
        {
            "x": -1,
            "y": 1,
            "z": 0,
            "elements": [
                "botania:livingrock@1"
            ]
        },
        {
            "x": 1,
            "y": 3,
            "z": 1,
            "elements": [
                "enderio:block_fused_glass@1",
				"enderio:block_fused_glass@2",
				"enderio:block_fused_glass@3",
				"enderio:block_fused_glass@4",
				"enderio:block_fused_glass@5",
				"enderio:block_fused_glass@6",
				"enderio:block_fused_glass@7",
				"enderio:block_fused_glass@8",
				"enderio:block_fused_glass@9",
				"enderio:block_fused_glass@10",
				"enderio:block_fused_glass@11",
				"enderio:block_fused_glass@12",
				"enderio:block_fused_glass@13",
				"enderio:block_fused_glass@14",
				"enderio:block_fused_glass@15"
            ]
        },
        {
            "x": 0,
            "y": 1,
            "z": 0,
            "elements": [
                "enderio:block_fused_glass@1",
				"enderio:block_fused_glass@2",
				"enderio:block_fused_glass@3",
				"enderio:block_fused_glass@4",
				"enderio:block_fused_glass@5",
				"enderio:block_fused_glass@6",
				"enderio:block_fused_glass@7",
				"enderio:block_fused_glass@8",
				"enderio:block_fused_glass@9",
				"enderio:block_fused_glass@10",
				"enderio:block_fused_glass@11",
				"enderio:block_fused_glass@12",
				"enderio:block_fused_glass@13",
				"enderio:block_fused_glass@14",
				"enderio:block_fused_glass@15"
            ]
        },
        {
            "x": -1,
            "y": 1,
            "z": 2,
            "elements": [
                "botania:livingrock@1"
            ]
        },
        {
            "x": 1,
            "y": 1,
            "z": 0,
            "elements": [
                "botania:livingrock@1"
            ]
        },
        {
            "x": 0,
            "y": 1,
            "z": 2,
            "elements": [
                "enderio:block_fused_glass@1",
				"enderio:block_fused_glass@2",
				"enderio:block_fused_glass@3",
				"enderio:block_fused_glass@4",
				"enderio:block_fused_glass@5",
				"enderio:block_fused_glass@6",
				"enderio:block_fused_glass@7",
				"enderio:block_fused_glass@8",
				"enderio:block_fused_glass@9",
				"enderio:block_fused_glass@10",
				"enderio:block_fused_glass@11",
				"enderio:block_fused_glass@12",
				"enderio:block_fused_glass@13",
				"enderio:block_fused_glass@14",
				"enderio:block_fused_glass@15"
            ]
        },
        {
            "x": 1,
            "y": 1,
            "z": 2,
            "elements": [
                "botania:livingrock@1"
            ]
        },
        {
            "x": -1,
            "y": 6,
            "z": 0,
            "elements": [
                "botania:livingrock@1"
            ]
        },
        {
            "x": 0,
            "y": 6,
            "z": 0,
            "elements": [
                "enderio:block_fused_glass@1",
				"enderio:block_fused_glass@2",
				"enderio:block_fused_glass@3",
				"enderio:block_fused_glass@4",
				"enderio:block_fused_glass@5",
				"enderio:block_fused_glass@6",
				"enderio:block_fused_glass@7",
				"enderio:block_fused_glass@8",
				"enderio:block_fused_glass@9",
				"enderio:block_fused_glass@10",
				"enderio:block_fused_glass@11",
				"enderio:block_fused_glass@12",
				"enderio:block_fused_glass@13",
				"enderio:block_fused_glass@14",
				"enderio:block_fused_glass@15"
            ]
        },
        {
            "x": -1,
            "y": 6,
            "z": 2,
            "elements": [
                "botania:livingrock@1"
            ]
        },
        {
            "x": 1,
            "y": 6,
            "z": 0,
            "elements": [
                "botania:livingrock@1"
            ]
        },
        {
            "x": 0,
            "y": 6,
            "z": 2,
            "elements": [
                "enderio:block_fused_glass@1",
				"enderio:block_fused_glass@2",
				"enderio:block_fused_glass@3",
				"enderio:block_fused_glass@4",
				"enderio:block_fused_glass@5",
				"enderio:block_fused_glass@6",
				"enderio:block_fused_glass@7",
				"enderio:block_fused_glass@8",
				"enderio:block_fused_glass@9",
				"enderio:block_fused_glass@10",
				"enderio:block_fused_glass@11",
				"enderio:block_fused_glass@12",
				"enderio:block_fused_glass@13",
				"enderio:block_fused_glass@14",
				"enderio:block_fused_glass@15"
            ]
        },
        {
            "x": 0,
            "y": 4,
            "z": 1,
            "elements": [
                "actuallyadditions:block_crystal_empowered@2"
            ]
        },
        {
            "x": 1,
            "y": 6,
            "z": 2,
            "elements": [
                "botania:livingrock@1"
            ]
        },
        {
            "x": -1,
            "y": 2,
            "z": 0,
            "elements": [
                "botania:livingrock@1"
            ]
        },
        {
            "x": 1,
            "y": 4,
            "z": 1,
            "elements": [
                "enderio:block_fused_glass@1",
				"enderio:block_fused_glass@2",
				"enderio:block_fused_glass@3",
				"enderio:block_fused_glass@4",
				"enderio:block_fused_glass@5",
				"enderio:block_fused_glass@6",
				"enderio:block_fused_glass@7",
				"enderio:block_fused_glass@8",
				"enderio:block_fused_glass@9",
				"enderio:block_fused_glass@10",
				"enderio:block_fused_glass@11",
				"enderio:block_fused_glass@12",
				"enderio:block_fused_glass@13",
				"enderio:block_fused_glass@14",
				"enderio:block_fused_glass@15"
            ]
        },
        {
            "x": 0,
            "y": 2,
            "z": 0,
            "elements": [
                "enderio:block_fused_glass@1",
				"enderio:block_fused_glass@2",
				"enderio:block_fused_glass@3",
				"enderio:block_fused_glass@4",
				"enderio:block_fused_glass@5",
				"enderio:block_fused_glass@6",
				"enderio:block_fused_glass@7",
				"enderio:block_fused_glass@8",
				"enderio:block_fused_glass@9",
				"enderio:block_fused_glass@10",
				"enderio:block_fused_glass@11",
				"enderio:block_fused_glass@12",
				"enderio:block_fused_glass@13",
				"enderio:block_fused_glass@14",
				"enderio:block_fused_glass@15"
            ]
        },
        {
            "x": -1,
            "y": 2,
            "z": 2,
            "elements": [
                "botania:livingrock@1"
            ]
        },
        {
            "x": 1,
            "y": 2,
            "z": 0,
            "elements": [
                "botania:livingrock@1"
            ]
        },
        {
            "x": -1,
            "y": 0,
            "z": 1,
            "elements": [
                "modularmachinery:blockinputbus@0",
                "modularmachinery:blockinputbus@1",
                "modularmachinery:blockinputbus@2",
                "modularmachinery:blockinputbus@3",
                "modularmachinery:blockinputbus@4",
                "modularmachinery:blockinputbus@5",
                "modularmachinery:blockinputbus@6",
                "modularmachinery:blockenergyinputhatch@0",
                "modularmachinery:blockenergyinputhatch@1",
                "modularmachinery:blockenergyinputhatch@2",
                "modularmachinery:blockenergyinputhatch@3",
                "modularmachinery:blockenergyinputhatch@4",
                "modularmachinery:blockenergyinputhatch@5",
                "modularmachinery:blockenergyinputhatch@6",
                "modularmachinery:blockenergyinputhatch@7",
                "modularmachinery:blockoutputbus@0",
                "modularmachinery:blockoutputbus@1",
                "modularmachinery:blockoutputbus@2",
                "modularmachinery:blockoutputbus@3",
                "modularmachinery:blockoutputbus@4",
                "modularmachinery:blockoutputbus@5",
                "modularmachinery:blockoutputbus@6"
            ]
        },
        {
            "x": 0,
            "y": 2,
            "z": 2,
            "elements": [
                "enderio:block_fused_glass@1",
				"enderio:block_fused_glass@2",
				"enderio:block_fused_glass@3",
				"enderio:block_fused_glass@4",
				"enderio:block_fused_glass@5",
				"enderio:block_fused_glass@6",
				"enderio:block_fused_glass@7",
				"enderio:block_fused_glass@8",
				"enderio:block_fused_glass@9",
				"enderio:block_fused_glass@10",
				"enderio:block_fused_glass@11",
				"enderio:block_fused_glass@12",
				"enderio:block_fused_glass@13",
				"enderio:block_fused_glass@14",
				"enderio:block_fused_glass@15"
            ]
        },
        {
            "x": 0,
            "y": 0,
            "z": 1,
            "elements": [
                "astralsorcery:blockblackmarble@0"
            ]
        },
        {
            "x": 1,
            "y": 2,
            "z": 2,
            "elements": [
                "botania:livingrock@1"
            ]
        },
        {
            "x": 1,
            "y": 0,
            "z": 1,
            "elements": [
                "modularmachinery:blockoutputbus@0",
                "modularmachinery:blockoutputbus@1",
                "modularmachinery:blockoutputbus@2",
                "modularmachinery:blockoutputbus@3",
                "modularmachinery:blockoutputbus@4",
                "modularmachinery:blockoutputbus@5",
                "modularmachinery:blockoutputbus@6",
                "modularmachinery:blockinputbus@0",
                "modularmachinery:blockinputbus@1",
                "modularmachinery:blockinputbus@2",
                "modularmachinery:blockinputbus@3",
                "modularmachinery:blockinputbus@4",
                "modularmachinery:blockinputbus@5",
                "modularmachinery:blockinputbus@6",
                "modularmachinery:blockenergyinputhatch@0",
                "modularmachinery:blockenergyinputhatch@1",
                "modularmachinery:blockenergyinputhatch@2",
                "modularmachinery:blockenergyinputhatch@3",
                "modularmachinery:blockenergyinputhatch@4",
                "modularmachinery:blockenergyinputhatch@5",
                "modularmachinery:blockenergyinputhatch@6",
                "modularmachinery:blockenergyinputhatch@7"
            ]
        },
        {
            "x": -1,
            "y": 7,
            "z": 0,
            "elements": [
                "contenttweaker:sub_block_holder_1@9"
            ]
        },
        {
            "x": 0,
            "y": 7,
            "z": 0,
            "elements": [
                "actuallyadditions:block_quartz_stair"
            ]
        },
        {
            "x": 1,
            "y": 7,
            "z": 0,
            "elements": [
                "contenttweaker:sub_block_holder_1@9"
            ]
        },
        {
            "x": -1,
            "y": 7,
            "z": 2,
            "elements": [
                "contenttweaker:sub_block_holder_1@9"
            ]
        },
        {
            "x": 0,
            "y": 7,
            "z": 2,
            "elements": [
                "actuallyadditions:block_quartz_stair"
            ]
        },
        {
            "x": 0,
            "y": 5,
            "z": 1,
            "elements": [
                "actuallyadditions:block_crystal_empowered@2"
            ]
        },
        {
            "x": -1,
            "y": 3,
            "z": 0,
            "elements": [
                "mekanism:plasticblock"
            ]
        },
        {
            "x": 1,
            "y": 7,
            "z": 2,
            "elements": [
                "contenttweaker:sub_block_holder_1@9"
            ]
        },
        {
            "x": 1,
            "y": 5,
            "z": 1,
            "elements": [
                "enderio:block_fused_glass@1",
				"enderio:block_fused_glass@2",
				"enderio:block_fused_glass@3",
				"enderio:block_fused_glass@4",
				"enderio:block_fused_glass@5",
				"enderio:block_fused_glass@6",
				"enderio:block_fused_glass@7",
				"enderio:block_fused_glass@8",
				"enderio:block_fused_glass@9",
				"enderio:block_fused_glass@10",
				"enderio:block_fused_glass@11",
				"enderio:block_fused_glass@12",
				"enderio:block_fused_glass@13",
				"enderio:block_fused_glass@14",
				"enderio:block_fused_glass@15"
            ]
        },
        {
            "x": 0,
            "y": 3,
            "z": 0,
            "elements": [
                "enderio:block_fused_glass@1",
				"enderio:block_fused_glass@2",
				"enderio:block_fused_glass@3",
				"enderio:block_fused_glass@4",
				"enderio:block_fused_glass@5",
				"enderio:block_fused_glass@6",
				"enderio:block_fused_glass@7",
				"enderio:block_fused_glass@8",
				"enderio:block_fused_glass@9",
				"enderio:block_fused_glass@10",
				"enderio:block_fused_glass@11",
				"enderio:block_fused_glass@12",
				"enderio:block_fused_glass@13",
				"enderio:block_fused_glass@14",
				"enderio:block_fused_glass@15"
            ]
        },
        {
            "x": 1,
            "y": 3,
            "z": 0,
            "elements": [
                "mekanism:plasticblock"
            ]
        },
        {
            "x": -1,
            "y": 3,
            "z": 2,
            "elements": [
                "mekanism:plasticblock"
            ]
        },
        {
            "x": 0,
            "y": 3,
            "z": 2,
            "elements": [
                "enderio:block_fused_glass@1",
				"enderio:block_fused_glass@2",
				"enderio:block_fused_glass@3",
				"enderio:block_fused_glass@4",
				"enderio:block_fused_glass@5",
				"enderio:block_fused_glass@6",
				"enderio:block_fused_glass@7",
				"enderio:block_fused_glass@8",
				"enderio:block_fused_glass@9",
				"enderio:block_fused_glass@10",
				"enderio:block_fused_glass@11",
				"enderio:block_fused_glass@12",
				"enderio:block_fused_glass@13",
				"enderio:block_fused_glass@14",
				"enderio:block_fused_glass@15"
            ]
        },
        {
            "x": 0,
            "y": 1,
            "z": 1,
            "elements": [
                "actuallyadditions:block_crystal_empowered@2"
            ]
        },
        {
            "x": 1,
            "y": 3,
            "z": 2,
            "elements": [
                "mekanism:plasticblock"
            ]
        },
        {
            "x": 1,
            "y": 1,
            "z": 1,
            "elements": [
                "enderio:block_fused_glass@1",
				"enderio:block_fused_glass@2",
				"enderio:block_fused_glass@3",
				"enderio:block_fused_glass@4",
				"enderio:block_fused_glass@5",
				"enderio:block_fused_glass@6",
				"enderio:block_fused_glass@7",
				"enderio:block_fused_glass@8",
				"enderio:block_fused_glass@9",
				"enderio:block_fused_glass@10",
				"enderio:block_fused_glass@11",
				"enderio:block_fused_glass@12",
				"enderio:block_fused_glass@13",
				"enderio:block_fused_glass@14",
				"enderio:block_fused_glass@15"
            ]
        },
        {
            "x": 0,
            "y": 6,
            "z": 1,
            "elements": [
                "actuallyadditions:block_crystal_empowered@2"
            ]
        },
        {
            "x": -1,
            "y": 4,
            "z": 0,
            "elements": [
                "botania:livingrock@1"
            ]
        },
        {
            "x": 1,
            "y": 6,
            "z": 1,
            "elements": [
                "enderio:block_fused_glass@1",
				"enderio:block_fused_glass@2",
				"enderio:block_fused_glass@3",
				"enderio:block_fused_glass@4",
				"enderio:block_fused_glass@5",
				"enderio:block_fused_glass@6",
				"enderio:block_fused_glass@7",
				"enderio:block_fused_glass@8",
				"enderio:block_fused_glass@9",
				"enderio:block_fused_glass@10",
				"enderio:block_fused_glass@11",
				"enderio:block_fused_glass@12",
				"enderio:block_fused_glass@13",
				"enderio:block_fused_glass@14",
				"enderio:block_fused_glass@15"
            ]
        },
        {
            "x": 0,
            "y": 4,
            "z": 0,
            "elements": [
                "enderio:block_fused_glass@1",
				"enderio:block_fused_glass@2",
				"enderio:block_fused_glass@3",
				"enderio:block_fused_glass@4",
				"enderio:block_fused_glass@5",
				"enderio:block_fused_glass@6",
				"enderio:block_fused_glass@7",
				"enderio:block_fused_glass@8",
				"enderio:block_fused_glass@9",
				"enderio:block_fused_glass@10",
				"enderio:block_fused_glass@11",
				"enderio:block_fused_glass@12",
				"enderio:block_fused_glass@13",
				"enderio:block_fused_glass@14",
				"enderio:block_fused_glass@15"
            ]
        },
        {
            "x": -1,
            "y": 4,
            "z": 2,
            "elements": [
                "botania:livingrock@1"
            ]
        },
        {
            "x": 1,
            "y": 4,
            "z": 0,
            "elements": [
                "botania:livingrock@1"
            ]
        },
        {
            "x": 0,
            "y": 4,
            "z": 2,
            "elements": [
                "enderio:block_fused_glass@1",
				"enderio:block_fused_glass@2",
				"enderio:block_fused_glass@3",
				"enderio:block_fused_glass@4",
				"enderio:block_fused_glass@5",
				"enderio:block_fused_glass@6",
				"enderio:block_fused_glass@7",
				"enderio:block_fused_glass@8",
				"enderio:block_fused_glass@9",
				"enderio:block_fused_glass@10",
				"enderio:block_fused_glass@11",
				"enderio:block_fused_glass@12",
				"enderio:block_fused_glass@13",
				"enderio:block_fused_glass@14",
				"enderio:block_fused_glass@15"
            ]
        },
        {
            "x": 0,
            "y": 2,
            "z": 1,
            "elements": [
                "actuallyadditions:block_crystal_empowered@2"
            ]
        },
        {
            "x": 1,
            "y": 4,
            "z": 2,
            "elements": [
                "botania:livingrock@1"
            ]
        },
        {
            "x": -1,
            "y": 6,
            "z": 1,
            "elements": [
                "enderio:block_fused_glass@1",
                "enderio:block_fused_glass@2",
                "enderio:block_fused_glass@3",
                "enderio:block_fused_glass@4",
                "enderio:block_fused_glass@5",
                "enderio:block_fused_glass@6",
                "enderio:block_fused_glass@7",
                "enderio:block_fused_glass@8",
                "enderio:block_fused_glass@9",
                "enderio:block_fused_glass@10",
                "enderio:block_fused_glass@11",
                "enderio:block_fused_glass@12",
                "enderio:block_fused_glass@13",
                "enderio:block_fused_glass@14",
                "enderio:block_fused_glass@15"
            ]
        },
        {
            "x": -1,
            "y": 5,
            "z": 1,
            "elements": [
                "enderio:block_fused_glass@1",
                "enderio:block_fused_glass@2",
                "enderio:block_fused_glass@3",
                "enderio:block_fused_glass@4",
                "enderio:block_fused_glass@5",
                "enderio:block_fused_glass@6",
                "enderio:block_fused_glass@7",
                "enderio:block_fused_glass@8",
                "enderio:block_fused_glass@9",
                "enderio:block_fused_glass@10",
                "enderio:block_fused_glass@11",
                "enderio:block_fused_glass@12",
                "enderio:block_fused_glass@13",
                "enderio:block_fused_glass@14",
                "enderio:block_fused_glass@15"
            ]
        },
        {
            "x": -1,
            "y": 4,
            "z": 1,
            "elements": [
                "enderio:block_fused_glass@1",
                "enderio:block_fused_glass@2",
                "enderio:block_fused_glass@3",
                "enderio:block_fused_glass@4",
                "enderio:block_fused_glass@5",
                "enderio:block_fused_glass@6",
                "enderio:block_fused_glass@7",
                "enderio:block_fused_glass@8",
                "enderio:block_fused_glass@9",
                "enderio:block_fused_glass@10",
                "enderio:block_fused_glass@11",
                "enderio:block_fused_glass@12",
                "enderio:block_fused_glass@13",
                "enderio:block_fused_glass@14",
                "enderio:block_fused_glass@15"
            ]
        },
        {
            "x": -1,
            "y": 3,
            "z": 1,
            "elements": [
                "enderio:block_fused_glass@1",
                "enderio:block_fused_glass@2",
                "enderio:block_fused_glass@3",
                "enderio:block_fused_glass@4",
                "enderio:block_fused_glass@5",
                "enderio:block_fused_glass@6",
                "enderio:block_fused_glass@7",
                "enderio:block_fused_glass@8",
                "enderio:block_fused_glass@9",
                "enderio:block_fused_glass@10",
                "enderio:block_fused_glass@11",
                "enderio:block_fused_glass@12",
                "enderio:block_fused_glass@13",
                "enderio:block_fused_glass@14",
                "enderio:block_fused_glass@15"
            ]
        },
        {
            "x": -1,
            "y": 2,
            "z": 1,
            "elements": [
                "enderio:block_fused_glass@1",
                "enderio:block_fused_glass@2",
                "enderio:block_fused_glass@3",
                "enderio:block_fused_glass@4",
                "enderio:block_fused_glass@5",
                "enderio:block_fused_glass@6",
                "enderio:block_fused_glass@7",
                "enderio:block_fused_glass@8",
                "enderio:block_fused_glass@9",
                "enderio:block_fused_glass@10",
                "enderio:block_fused_glass@11",
                "enderio:block_fused_glass@12",
                "enderio:block_fused_glass@13",
                "enderio:block_fused_glass@14",
                "enderio:block_fused_glass@15"
            ]
        },
        {
            "x": -1,
            "y": 1,
            "z": 1,
            "elements": [
                "enderio:block_fused_glass@1",
                "enderio:block_fused_glass@2",
                "enderio:block_fused_glass@3",
                "enderio:block_fused_glass@4",
                "enderio:block_fused_glass@5",
                "enderio:block_fused_glass@6",
                "enderio:block_fused_glass@7",
                "enderio:block_fused_glass@8",
                "enderio:block_fused_glass@9",
                "enderio:block_fused_glass@10",
                "enderio:block_fused_glass@11",
                "enderio:block_fused_glass@12",
                "enderio:block_fused_glass@13",
                "enderio:block_fused_glass@14",
                "enderio:block_fused_glass@15"
            ]
        }
    ],
    "modifiers": [
        {
            "elements": "contenttweaker:mmupgrade_speed",
            "x": 0,
            "y": 1,
            "z": 0,
            "description": "Replace block above controller with MM Machine Speed Upgrade\nfor double processing speed",
            "modifier": {
                "io": "input",
                "target": "duration",
                "operation": 1,
                "multiplier": -2.0
            }
        },
        {
            "elements": "contenttweaker:mmupgrade_efficiancy_item",
            "x": 0,
            "y": 1,
            "z": 0,
            "description": "Replace block above controller with MM Machine Speed Upgrade\nfor double item output",
            "modifier": {
                "io": "output",
                "target": "item",
                "operation": 1,
                "multiplier": 2.0
            }
        },
        {
            "elements": "contenttweaker:mmupgrade_efficiancy_fluid",
            "x": 0,
            "y": 1,
            "z": 0,
            "description": "Replace block above controller with MM Machine Speed Upgrade\nfor double fluid output",
            "modifier": {
                "io": "output",
                "target": "fluid",
                "operation": 1,
                "multiplier": 2.0
            }
        },
        {
            "elements": "contenttweaker:mmupgrade_efficiancy_energy",
            "x": 0,
            "y": 1,
            "z": 0,
            "description": "Replace block above controller with MM Machine Speed Upgrade\nfor double energy output",
            "modifier": {
                "io": "output",
                "target": "energy",
                "operation": 1,
                "multiplier": 2.0
            }
        }
    ]
}