{
    "registryname": "oil_generator_mk1",
    "localizedname": "Modular Oil Generator MK1",
    "requires-blueprint": true,
    "color": "9c6528",
	"parts": [
        {
            "x": -1,
            "y": 0,
            "z": 0,
            "elements": [
                "immersiveengineering:sheetmetal@9"
            ]
        },
        {
            "x": -1,
            "y": 0,
            "z": 1,
            "elements": [
                "modularmachinery:blockenergyoutputhatch@1",
				"modularmachinery:blockenergyoutputhatch@2",
				"modularmachinery:blockenergyoutputhatch@3",
				"modularmachinery:blockenergyoutputhatch@4",
				"modularmachinery:blockenergyoutputhatch@5",
				"modularmachinery:blockenergyoutputhatch@6",
                "modularmachinery:blockenergyoutputhatch@7",
				"modularmachinery:blockfluidinputhatch@0",
				"modularmachinery:blockfluidinputhatch@1",
				"modularmachinery:blockfluidinputhatch@2",
				"modularmachinery:blockfluidinputhatch@3",
				"modularmachinery:blockfluidinputhatch@4",
				"modularmachinery:blockfluidinputhatch@5",
				"modularmachinery:blockfluidinputhatch@6"
            ]
        },
        {
            "x": 0,
            "y": 2,
            "z": 2,
            "elements": [
                "immersiveengineering:sheetmetal@8"
            ]
        },
        {
            "x": 1,
            "y": 2,
            "z": 1,
            "elements": [
                "immersiveengineering:sheetmetal@9"
            ]
        },
        {
            "x": 0,
            "y": 0,
            "z": 1,
            "elements": [
                "immersiveengineering:sheetmetal@9"
            ]
        },
        {
            "x": 1,
            "y": 2,
            "z": -1,
            "elements": [
                "immersiveengineering:metal_decoration1@1"
            ]
        },
        {
            "x": 1,
            "y": 0,
            "z": 0,
            "elements": [
                "immersiveengineering:sheetmetal@9"
            ]
        },
        {
            "x": -1,
            "y": 0,
            "z": 2,
            "elements": [
                "immersiveengineering:sheetmetal@8"
            ]
        },
        {
            "x": 1,
            "y": 2,
            "z": 2,
            "elements": [
                "immersiveengineering:sheetmetal@8"
            ]
        },
        {
            "x": 1,
            "y": 0,
            "z": 1,
            "elements": [
                "modularmachinery:blockfluidinputhatch@0",
				"modularmachinery:blockfluidinputhatch@1",
				"modularmachinery:blockfluidinputhatch@2",
				"modularmachinery:blockfluidinputhatch@3",
				"modularmachinery:blockfluidinputhatch@4",
				"modularmachinery:blockfluidinputhatch@5",
				"modularmachinery:blockfluidinputhatch@6",
				"modularmachinery:blockenergyoutputhatch@1",
				"modularmachinery:blockenergyoutputhatch@2",
				"modularmachinery:blockenergyoutputhatch@3",
				"modularmachinery:blockenergyoutputhatch@4",
				"modularmachinery:blockenergyoutputhatch@5",
				"modularmachinery:blockenergyoutputhatch@6",
                "modularmachinery:blockenergyoutputhatch@7"
            ]
        },
        {
            "x": 0,
            "y": 0,
            "z": 2,
            "elements": [
                "immersiveengineering:sheetmetal@8"
            ]
        },
        {
            "x": 1,
            "y": 0,
            "z": 2,
            "elements": [
                "immersiveengineering:sheetmetal@8"
            ]
        },
        {
            "x": 1,
            "y": -1,
            "z": 0,
            "elements": [
                "immersiveengineering:sheetmetal@9"
            ]
        },
        {
            "x": 1,
            "y": 3,
            "z": 0,
            "elements": [
                "immersiveengineering:metal_decoration1@1"
            ]
        },
        {
            "x": 0,
            "y": -1,
            "z": 0,
            "elements": [
                "immersiveengineering:sheetmetal@9"
            ]
        },
        {
            "x": -1,
            "y": 1,
            "z": 0,
            "elements": [
                "immersiveengineering:sheetmetal@9"
            ]
        },
        {
            "x": 1,
            "y": -1,
            "z": -1,
            "elements": [
                "immersiveengineering:metal_decoration1@1"
            ]
        },
        {
            "x": -1,
            "y": -1,
            "z": 0,
            "elements": [
                "immersiveengineering:sheetmetal@9"
            ]
        },
        {
            "x": 0,
            "y": 1,
            "z": 0,
            "elements": [
                "immersiveengineering:metal_decoration0@3"
            ]
        },
        {
            "x": -1,
            "y": 1,
            "z": 1,
            "elements": [
                "immersiveengineering:sheetmetal@9"
            ]
        },
        {
            "x": 0,
            "y": 1,
            "z": 1,
            "elements": [
                "immersiveengineering:sheetmetal@9"
            ]
        },
        {
            "x": 1,
            "y": 1,
            "z": 0,
            "elements": [
                "immersiveengineering:sheetmetal@9"
            ]
        },
        {
            "x": 1,
            "y": 1,
            "z": -1,
            "elements": [
                "immersiveengineering:metal_decoration1@1"
            ]
        },
        {
            "x": -1,
            "y": 1,
            "z": 2,
            "elements": [
                "immersiveengineering:sheetmetal@8"
            ]
        },
        {
            "x": 0,
            "y": 1,
            "z": 2,
            "elements": [
                "immersiveengineering:sheetmetal@8"
            ]
        },
        {
            "x": 1,
            "y": 1,
            "z": 1,
            "elements": [
                "immersiveengineering:sheetmetal@9"
            ]
        },
        {
            "x": -1,
            "y": -1,
            "z": 1,
            "elements": [
                "immersiveengineering:sheetmetal@9"
            ]
        },
        {
            "x": 1,
            "y": 1,
            "z": 2,
            "elements": [
                "immersiveengineering:sheetmetal@8"
            ]
        },
        {
            "x": 1,
            "y": 3,
            "z": -1,
            "elements": [
                "immersiveengineering:metal_decoration1@1"
            ]
        },
        {
            "x": 0,
            "y": -1,
            "z": 1,
            "elements": [
                "immersiveengineering:sheetmetal@9"
            ]
        },
        {
            "x": -1,
            "y": -1,
            "z": 2,
            "elements": [
                "immersiveengineering:sheetmetal@8"
            ]
        },
        {
            "x": 0,
            "y": -1,
            "z": 2,
            "elements": [
                "immersiveengineering:sheetmetal@8"
            ]
        },
        {
            "x": 1,
            "y": -1,
            "z": 1,
            "elements": [
                "immersiveengineering:sheetmetal@9"
            ]
        },
        {
            "x": 1,
            "y": -1,
            "z": 2,
            "elements": [
                "immersiveengineering:sheetmetal@8"
            ]
        },
        {
            "x": -1,
            "y": 2,
            "z": 0,
            "elements": [
                "immersiveengineering:sheetmetal@9"
            ]
        },
        {
            "x": -1,
            "y": 2,
            "z": 1,
            "elements": [
                "immersiveengineering:sheetmetal@9"
            ]
        },
        {
            "x": 0,
            "y": 2,
            "z": 0,
            "elements": [
                "immersiveengineering:metal_decoration0@4"
            ]
        },
        {
            "x": 1,
            "y": 0,
            "z": -1,
            "elements": [
                "immersiveengineering:metal_decoration1@1"
            ]
        },
        {
            "x": -1,
            "y": 2,
            "z": 2,
            "elements": [
                "immersiveengineering:sheetmetal@8"
            ]
        },
        {
            "x": 0,
            "y": 2,
            "z": 1,
            "elements": [
                "immersiveengineering:sheetmetal@9"
            ]
        },
        {
            "x": 1,
            "y": 2,
            "z": 0,
            "elements": [
                "immersiveengineering:sheetmetal@9"
            ]
        }
    ],
    "modifiers": [
        {
            "elements": "contenttweaker:mmupgrade_speed",
            "x": 0,
            "y": 1,
            "z": 0,
            "description": "Replace block above controller with MM Machine Speed Upgrade\nfor double processing speed",
            "modifier": {
                "io": "input",
                "target": "duration",
                "operation": 1,
                "multiplier": 0.5
            }
        },
        {
            "elements": "contenttweaker:mmupgrade_efficiancy_item",
            "x": 0,
            "y": 1,
            "z": 0,
            "description": "Replace block above controller with MM Machine Speed Upgrade\nfor double item output",
            "modifier": {
                "io": "output",
                "target": "item",
                "operation": 1,
                "multiplier": 2.0
            }
        },
        {
            "elements": "contenttweaker:mmupgrade_efficiancy_fluid",
            "x": 0,
            "y": 1,
            "z": 0,
            "description": "Replace block above controller with MM Machine Speed Upgrade\nfor double fluid output",
            "modifier": {
                "io": "output",
                "target": "fluid",
                "operation": 1,
                "multiplier": 2.0
            }
        },
        {
            "elements": "contenttweaker:mmupgrade_efficiancy_energy",
            "x": 0,
            "y": 1,
            "z": 0,
            "description": "Replace block above controller with MM Machine Speed Upgrade\nfor double energy output",
            "modifier": {
                "io": "output",
                "target": "energy",
                "operation": 1,
                "multiplier": 2.0
            }
        }
    ]
}
