{
    "registryname": "resurgence",
    "localizedname": "Resurgence Machinery",
    "requires-blueprint": true,
    "color": "141005",
	"parts": [
        {
            "x": -1,
            "y": 0,
            "z": 0,
            "elements": [
                "modularmachinery:blockoutputbus@0",
				"modularmachinery:blockoutputbus@1",
				"modularmachinery:blockoutputbus@2",
				"modularmachinery:blockoutputbus@3",
				"modularmachinery:blockoutputbus@4",
				"modularmachinery:blockoutputbus@5",
				"modularmachinery:blockoutputbus@6",
				"modulardiversity:blockmanainputhatch@0",
				"modularmachinery:blockinputbus@0",
				"modularmachinery:blockinputbus@1",
				"modularmachinery:blockinputbus@2",
				"modularmachinery:blockinputbus@3",
				"modularmachinery:blockinputbus@4",
				"modularmachinery:blockinputbus@5",
				"modularmachinery:blockinputbus@6"
            ]
        },
        {
            "x": -1,
            "y": 0,
            "z": 1,
            "elements": [
                "contenttweaker:ice_soulsand@0"
            ]
        },
        {
            "x": 1,
            "y": 2,
            "z": 1,
            "elements": [
                "quark:biome_brick@1"
            ]
        },
        {
            "x": 0,
            "y": 0,
            "z": 1,
            "elements": [
                "contenttweaker:ice_magma@0"
            ]
        },
        {
            "x": 1,
            "y": 0,
            "z": 0,
            "elements": [
                "modularmachinery:blockinputbus@0",
				"modularmachinery:blockinputbus@1",
				"modularmachinery:blockinputbus@2",
				"modularmachinery:blockinputbus@3",
				"modularmachinery:blockinputbus@4",
				"modularmachinery:blockinputbus@5",
				"modularmachinery:blockinputbus@6",
				"modularmachinery:blockoutputbus@0",
				"modularmachinery:blockoutputbus@1",
				"modularmachinery:blockoutputbus@2",
				"modularmachinery:blockoutputbus@3",
				"modularmachinery:blockoutputbus@4",
				"modularmachinery:blockoutputbus@5",
				"modularmachinery:blockoutputbus@6",
				"modulardiversity:blockmanainputhatch@0"
            ]
        },
        {
            "x": -1,
            "y": 0,
            "z": 2,
            "elements": [
                "quark:biome_brick@1"
            ]
        },
        {
            "x": 1,
            "y": 0,
            "z": 1,
            "elements": [
                "contenttweaker:ice_soulsand@0"
            ]
        },
        {
            "x": 0,
            "y": 0,
            "z": 2,
            "elements": [
                "contenttweaker:ice_magma@0"
            ]
        },
        {
            "x": -1,
            "y": 0,
            "z": 3,
            "elements": [
                "quark:biome_brick@1"
            ]
        },
        {
            "x": 2,
            "y": 0,
            "z": 1,
            "elements": [
                "quark:biome_brick@1"
            ]
        },
        {
            "x": 0,
            "y": 0,
            "z": 3,
            "elements": [
                "contenttweaker:ice_magma@0"
            ]
        },
        {
            "x": 1,
            "y": 0,
            "z": 2,
            "elements": [
                "quark:biome_brick@1"
            ]
        },
        {
            "x": 0,
            "y": 0,
            "z": 4,
            "elements": [
                "quark:biome_brick@1"
            ]
        },
        {
            "x": 1,
            "y": 0,
            "z": 3,
            "elements": [
                "quark:biome_brick@1"
            ]
        },
        {
            "x": 1,
            "y": -1,
            "z": 0,
            "elements": [
                "quark:biome_brick@1"
            ]
        },
        {
            "x": 0,
            "y": -1,
            "z": 0,
            "elements": [
                "quark:biome_brick@1"
            ]
        },
        {
            "x": -1,
            "y": 1,
            "z": 0,
            "elements": [
                "quark:biome_brick@1"
            ]
        },
        {
            "x": -2,
            "y": 1,
            "z": 1,
            "elements": [
                "quark:biome_brick@1"
            ]
        },
        {
            "x": -1,
            "y": -1,
            "z": 0,
            "elements": [
                "quark:biome_brick@1"
            ]
        },
        {
            "x": 0,
            "y": 1,
            "z": 0,
            "elements": [
                "modulardiversity:blockmanainputhatch@0",
				"modularmachinery:blockinputbus@0",
				"modularmachinery:blockinputbus@1",
				"modularmachinery:blockinputbus@2",
				"modularmachinery:blockinputbus@3",
				"modularmachinery:blockinputbus@4",
				"modularmachinery:blockinputbus@5",
				"modularmachinery:blockinputbus@6",
				"modularmachinery:blockoutputbus@0",
				"modularmachinery:blockoutputbus@1",
				"modularmachinery:blockoutputbus@2",
				"modularmachinery:blockoutputbus@3",
				"modularmachinery:blockoutputbus@4",
				"modularmachinery:blockoutputbus@5",
				"modularmachinery:blockoutputbus@6"
            ]
        },
        {
            "x": -1,
            "y": 1,
            "z": 1,
            "elements": [
                "contenttweaker:ice_soulsand@0"
            ]
        },
        {
            "x": 0,
            "y": 1,
            "z": 1,
            "elements": [
                "contenttweaker:ice_magma@0"
            ]
        },
        {
            "x": 1,
            "y": 1,
            "z": 0,
            "elements": [
                "quark:biome_brick@1"
            ]
        },
        {
            "x": -1,
            "y": 1,
            "z": 2,
            "elements": [
                "quark:biome_brick@1"
            ]
        },
        {
            "x": 0,
            "y": 1,
            "z": 2,
            "elements": [
                "quark:biome_brick@1"
            ]
        },
        {
            "x": 1,
            "y": 1,
            "z": 1,
            "elements": [
                "contenttweaker:ice_soulsand@0"
            ]
        },
        {
            "x": -1,
            "y": -1,
            "z": 1,
            "elements": [
                "quark:biome_brick@1"
            ]
        },
        {
            "x": 0,
            "y": 1,
            "z": 3,
            "elements": [
                "quark:biome_brick@1"
            ]
        },
        {
            "x": 1,
            "y": 1,
            "z": 2,
            "elements": [
                "quark:biome_brick@1"
            ]
        },
        {
            "x": 0,
            "y": -1,
            "z": 1,
            "elements": [
                "quark:biome_brick@1"
            ]
        },
        {
            "x": 2,
            "y": 1,
            "z": 1,
            "elements": [
                "quark:biome_brick@1"
            ]
        },
        {
            "x": -1,
            "y": -1,
            "z": 2,
            "elements": [
                "quark:biome_brick@1"
            ]
        },
        {
            "x": 0,
            "y": -1,
            "z": 2,
            "elements": [
                "quark:biome_brick@1"
            ]
        },
        {
            "x": 1,
            "y": -1,
            "z": 1,
            "elements": [
                "quark:biome_brick@1"
            ]
        },
        {
            "x": -1,
            "y": -1,
            "z": 3,
            "elements": [
                "quark:biome_brick@1"
            ]
        },
        {
            "x": 1,
            "y": -1,
            "z": 2,
            "elements": [
                "quark:biome_brick@1"
            ]
        },
        {
            "x": 0,
            "y": -1,
            "z": 3,
            "elements": [
                "quark:biome_brick@1"
            ]
        },
        {
            "x": 1,
            "y": -1,
            "z": 3,
            "elements": [
                "quark:biome_brick@1"
            ]
        },
        {
            "x": -1,
            "y": 2,
            "z": 1,
            "elements": [
                "quark:biome_brick@1"
            ]
        },
        {
            "x": -2,
            "y": 0,
            "z": 1,
            "elements": [
                "quark:biome_brick@1"
            ]
        },
        {
            "x": 0,
            "y": 2,
            "z": 1,
            "elements": [
                "quark:biome_brick@1"
            ]
        }
    ],
    "modifiers": [
        {
            "elements": "contenttweaker:mmupgrade_speed",
            "x": 0,
            "y": 1,
            "z": 0,
            "description": "Replace block above controller with MM Machine Speed Upgrade\nfor double processing speed",
            "modifier": {
                "io": "input",
                "target": "duration",
                "operation": 1,
                "multiplier": -2.0
            }
        },
        {
            "elements": "contenttweaker:mmupgrade_efficiancy_item",
            "x": 0,
            "y": 1,
            "z": 0,
            "description": "Replace block above controller with MM Machine Speed Upgrade\nfor double item output",
            "modifier": {
                "io": "output",
                "target": "item",
                "operation": 1,
                "multiplier": 2.0
            }
        },
        {
            "elements": "contenttweaker:mmupgrade_efficiancy_fluid",
            "x": 0,
            "y": 1,
            "z": 0,
            "description": "Replace block above controller with MM Machine Speed Upgrade\nfor double fluid output",
            "modifier": {
                "io": "output",
                "target": "fluid",
                "operation": 1,
                "multiplier": 2.0
            }
        },
        {
            "elements": "contenttweaker:mmupgrade_efficiancy_energy",
            "x": 0,
            "y": 1,
            "z": 0,
            "description": "Replace block above controller with MM Machine Speed Upgrade\nfor double energy output",
            "modifier": {
                "io": "output",
                "target": "energy",
                "operation": 1,
                "multiplier": 2.0
            }
        }
    ]
}
